Workbook

Sheet Datos
A1: Orden | B1: Parte | C1: Paso | D1: Portadora (MHz) | E1: Tono (kHz) | F1: Tasa (MSPS) | G1: Tono principal | H1: Corr. imagen | I1: Corr. e (fuga) | J1: Corr. d (tono) | K1: Linea a medir | L1: f esperada (MHz) | M1: SA START (MHz) | N1: SA STOP (MHz) | O1: Ventana (kHz) | P1: RBW (kHz) | Q1: Nivel de la correccion (dB) | R1: Fase de la correccion (grados) | S1: f medida (MHz) | T1: Nivel medido (dBm) | U1: Capturar a SD | V1: Que hacer antes de medir esta fila | W1: Notas
A2: 1 | B2: A | C2: Vista ancha | D2: 400 | E2: 200 | F2: 2 | G2: Enc | H2: Apag | I2: Apag | J2: Apag | K2: Vista ancha | L2: =IF($K2="Vista ancha",$D2+0.1,$D2+IF($K2="Fuga",0,IF($K2="Tono",$E2,IF($K2="Imagen",-$E2,IF($K2="Replica fuga",Parametros!$B$2,IF($K2="Replica tono",$E2+Parametros!$B$2,IF($K2="Gemela fuga",-Parametros!$B$2,IF($K2="Gemela tono",$E2-Parametros!$B$2,0)))))))/1000) | M2: =L2-O2/2000 | N2: =L2+O2/2000 | O2: 2600 | P2: 3 | U2: SI | V2: Montaje del EXP-08: cable directo, atenuacion 0 dB. En el flujo: 400 MHz, 200 kHz, ganancia 30, amplitud 0,5, 2 MSPS, tono encendido y todas las correcciones apagadas. Transmitir 5 minutos antes de medir. Promediado 16. En Notas, anotar toda linea que se vea por encima de -100 dBm con su frecuencia.
A3: 2 | B3: A | C3: Referencia | D3: 400 | E3: 200 | F3: 2 | G3: Enc | H3: Apag | I3: Apag | J3: Apag | K3: Fuga | L3: =IF($K3="Vista ancha",$D3+0.1,$D3+IF($K3="Fuga",0,IF($K3="Tono",$E3,IF($K3="Imagen",-$E3,IF($K3="Replica fuga",Parametros!$B$2,IF($K3="Replica tono",$E3+Parametros!$B$2,IF($K3="Gemela fuga",-Parametros!$B$2,IF($K3="Gemela tono",$E3-Parametros!$B$2,0)))))))/1000) | M3: =L3-O3/2000 | N3: =L3+O3/2000 | O3: 20 | P3: 1 | V3: Desde aca, ventana y filtro segun las columnas de cada fila. Promediado 16 salvo que se indique otra cosa.
A4: 3 | B4: A | C4: Referencia | D4: 400 | E4: 200 | F4: 2 | G4: Enc | H4: Apag | I4: Apag | J4: Apag | K4: Tono | L4: =IF($K4="Vista ancha",$D4+0.1,$D4+IF($K4="Fuga",0,IF($K4="Tono",$E4,IF($K4="Imagen",-$E4,IF($K4="Replica fuga",Parametros!$B$2,IF($K4="Replica tono",$E4+Parametros!$B$2,IF($K4="Gemela fuga",-Parametros!$B$2,IF($K4="Gemela tono",$E4-Parametros!$B$2,0)))))))/1000) | M4: =L4-O4/2000 | N4: =L4+O4/2000 | O4: 20 | P4: 1
A5: 4 | B5: A | C5: Replicas | D5: 400 | E5: 200 | F5: 2 | G5: Enc | H5: Apag | I5: Apag | J5: Apag | K5: Replica fuga | L5: =IF($K5="Vista ancha",$D5+0.1,$D5+IF($K5="Fuga",0,IF($K5="Tono",$E5,IF($K5="Imagen",-$E5,IF($K5="Replica fuga",Parametros!$B$2,IF($K5="Replica tono",$E5+Parametros!$B$2,IF($K5="Gemela fuga",-Parametros!$B$2,IF($K5="Gemela tono",$E5-Parametros!$B$2,0)))))))/1000) | M5: =L5-O5/2000 | N5: =L5+O5/2000 | O5: 20 | P5: 1
A6: 5 | B6: A | C6: Replicas | D6: 400 | E6: 200 | F6: 2 | G6: Enc | H6: Apag | I6: Apag | J6: Apag | K6: Replica tono | L6: =IF($K6="Vista ancha",$D6+0.1,$D6+IF($K6="Fuga",0,IF($K6="Tono",$E6,IF($K6="Imagen",-$E6,IF($K6="Replica fuga",Parametros!$B$2,IF($K6="Replica tono",$E6+Parametros!$B$2,IF($K6="Gemela fuga",-Parametros!$B$2,IF($K6="Gemela tono",$E6-Parametros!$B$2,0)))))))/1000) | M6: =L6-O6/2000 | N6: =L6+O6/2000 | O6: 20 | P6: 1
A7: 6 | B7: A | C7: Gemelas | D7: 400 | E7: 200 | F7: 2 | G7: Enc | H7: Apag | I7: Apag | J7: Apag | K7: Gemela fuga | L7: =IF($K7="Vista ancha",$D7+0.1,$D7+IF($K7="Fuga",0,IF($K7="Tono",$E7,IF($K7="Imagen",-$E7,IF($K7="Replica fuga",Parametros!$B$2,IF($K7="Replica tono",$E7+Parametros!$B$2,IF($K7="Gemela fuga",-Parametros!$B$2,IF($K7="Gemela tono",$E7-Parametros!$B$2,0)))))))/1000) | M7: =L7-O7/2000 | N7: =L7+O7/2000 | O7: 20 | P7: 1 | V7: Si no aparece ninguna linea, anotar el piso de ruido como nivel y escribir 'no aparece' en Notas.
A8: 7 | B8: A | C8: Gemelas | D8: 400 | E8: 200 | F8: 2 | G8: Enc | H8: Apag | I8: Apag | J8: Apag | K8: Gemela tono | L8: =IF($K8="Vista ancha",$D8+0.1,$D8+IF($K8="Fuga",0,IF($K8="Tono",$E8,IF($K8="Imagen",-$E8,IF($K8="Replica fuga",Parametros!$B$2,IF($K8="Replica tono",$E8+Parametros!$B$2,IF($K8="Gemela fuga",-Parametros!$B$2,IF($K8="Gemela tono",$E8-Parametros!$B$2,0)))))))/1000) | M8: =L8-O8/2000 | N8: =L8+O8/2000 | O8: 20 | P8: 1 | V8: Igual que la fila anterior si no aparece nada.
A9: 8 | B9: A | C9: Frecuencia exacta | D9: 400 | E9: 200 | F9: 2 | G9: Enc | H9: Apag | I9: Apag | J9: Apag | K9: Fuga | L9: =IF($K9="Vista ancha",$D9+0.1,$D9+IF($K9="Fuga",0,IF($K9="Tono",$E9,IF($K9="Imagen",-$E9,IF($K9="Replica fuga",Parametros!$B$2,IF($K9="Replica tono",$E9+Parametros!$B$2,IF($K9="Gemela fuga",-Parametros!$B$2,IF($K9="Gemela tono",$E9-Parametros!$B$2,0)))))))/1000) | M9: =L9-O9/2000 | N9: =L9+O9/2000 | O9: 2 | P9: 0.2 | V9: Ventana de 2 kHz y filtro de 200 Hz. Marcador en el pico. Anotar la frecuencia del marcador con todos los decimales en la columna 'f medida'.
A10: 9 | B10: A | C10: Frecuencia exacta | D10: 400 | E10: 200 | F10: 2 | G10: Enc | H10: Apag | I10: Apag | J10: Apag | K10: Replica fuga | L10: =IF($K10="Vista ancha",$D10+0.1,$D10+IF($K10="Fuga",0,IF($K10="Tono",$E10,IF($K10="Imagen",-$E10,IF($K10="Replica fuga",Parametros!$B$2,IF($K10="Replica tono",$E10+Parametros!$B$2,IF($K10="Gemela fuga",-Parametros!$B$2,IF($K10="Gemela tono",$E10-Parametros!$B$2,0)))))))/1000) | M10: =L10-O10/2000 | N10: =L10+O10/2000 | O10: 2 | P10: 0.2 | V10: Igual que la fila anterior. Con estas dos filas la hoja Parametros calcula el corrimiento exacto y todas las ventanas se actualizan solas.
A11: 10 | B11: A | C11: Tono apagado | D11: 400 | E11: 200 | F11: 2 | G11: Apag | H11: Apag | I11: Apag | J11: Apag | K11: Replica fuga | L11: =IF($K11="Vista ancha",$D11+0.1,$D11+IF($K11="Fuga",0,IF($K11="Tono",$E11,IF($K11="Imagen",-$E11,IF($K11="Replica fuga",Parametros!$B$2,IF($K11="Replica tono",$E11+Parametros!$B$2,IF($K11="Gemela fuga",-Parametros!$B$2,IF($K11="Gemela tono",$E11-Parametros!$B$2,0)))))))/1000) | M11: =L11-O11/2000 | N11: =L11+O11/2000 | O11: 20 | P11: 1 | V11: Tono principal en Apagado.
A12: 11 | B12: A | C12: Tono apagado | D12: 400 | E12: 200 | F12: 2 | G12: Apag | H12: Apag | I12: Apag | J12: Apag | K12: Replica tono | L12: =IF($K12="Vista ancha",$D12+0.1,$D12+IF($K12="Fuga",0,IF($K12="Tono",$E12,IF($K12="Imagen",-$E12,IF($K12="Replica fuga",Parametros!$B$2,IF($K12="Replica tono",$E12+Parametros!$B$2,IF($K12="Gemela fuga",-Parametros!$B$2,IF($K12="Gemela tono",$E12-Parametros!$B$2,0)))))))/1000) | M12: =L12-O12/2000 | N12: =L12+O12/2000 | O12: 20 | P12: 1 | V12: Se espera que desaparezca. Si no se ve nada, anotar el piso.
A13: 12 | B13: A | C13: Tono con correccion de imagen | D13: 400 | E13: 200 | F13: 2 | G13: Enc | H13: Enc | I13: Apag | J13: Apag | K13: Tono | L13: =IF($K13="Vista ancha",$D13+0.1,$D13+IF($K13="Fuga",0,IF($K13="Tono",$E13,IF($K13="Imagen",-$E13,IF($K13="Replica fuga",Parametros!$B$2,IF($K13="Replica tono",$E13+Parametros!$B$2,IF($K13="Gemela fuga",-Parametros!$B$2,IF($K13="Gemela tono",$E13-Parametros!$B$2,0)))))))/1000) | M13: =L13-O13/2000 | N13: =L13+O13/2000 | O13: 20 | P13: 1 | V13: Tono principal Encendido. Correccion de imagen Encendida, con -34,5 dB y 15 grados. Las cuatro filas de tono se miden en la misma ventana, solo cambiando el interruptor.
A14: 13 | B14: A | C14: Tono con correccion de imagen | D14: 400 | E14: 200 | F14: 2 | G14: Enc | H14: Apag | I14: Apag | J14: Apag | K14: Tono | L14: =IF($K14="Vista ancha",$D14+0.1,$D14+IF($K14="Fuga",0,IF($K14="Tono",$E14,IF($K14="Imagen",-$E14,IF($K14="Replica fuga",Parametros!$B$2,IF($K14="Replica tono",$E14+Parametros!$B$2,IF($K14="Gemela fuga",-Parametros!$B$2,IF($K14="Gemela tono",$E14-Parametros!$B$2,0)))))))/1000) | M14: =L14-O14/2000 | N14: =L14+O14/2000 | O14: 20 | P14: 1 | V14: Correccion de imagen Apagada.
A15: 14 | B15: A | C15: Tono con correccion de imagen | D15: 400 | E15: 200 | F15: 2 | G15: Enc | H15: Enc | I15: Apag | J15: Apag | K15: Tono | L15: =IF($K15="Vista ancha",$D15+0.1,$D15+IF($K15="Fuga",0,IF($K15="Tono",$E15,IF($K15="Imagen",-$E15,IF($K15="Replica fuga",Parametros!$B$2,IF($K15="Replica tono",$E15+Parametros!$B$2,IF($K15="Gemela fuga",-Parametros!$B$2,IF($K15="Gemela tono",$E15-Parametros!$B$2,0)))))))/1000) | M15: =L15-O15/2000 | N15: =L15+O15/2000 | O15: 20 | P15: 1 | V15: Correccion de imagen Encendida.
A16: 15 | B16: A | C16: Replicas con correccion de imagen | D16: 400 | E16: 200 | F16: 2 | G16: Enc | H16: Enc | I16: Apag | J16: Apag | K16: Replica fuga | L16: =IF($K16="Vista ancha",$D16+0.1,$D16+IF($K16="Fuga",0,IF($K16="Tono",$E16,IF($K16="Imagen",-$E16,IF($K16="Replica fuga",Parametros!$B$2,IF($K16="Replica tono",$E16+Parametros!$B$2,IF($K16="Gemela fuga",-Parametros!$B$2,IF($K16="Gemela tono",$E16-Parametros!$B$2,0)))))))/1000) | M16: =L16-O16/2000 | N16: =L16+O16/2000 | O16: 20 | P16: 1
A17: 16 | B17: A | C17: Replicas con correccion de imagen | D17: 400 | E17: 200 | F17: 2 | G17: Enc | H17: Enc | I17: Apag | J17: Apag | K17: Replica tono | L17: =IF($K17="Vista ancha",$D17+0.1,$D17+IF($K17="Fuga",0,IF($K17="Tono",$E17,IF($K17="Imagen",-$E17,IF($K17="Replica fuga",Parametros!$B$2,IF($K17="Replica tono",$E17+Parametros!$B$2,IF($K17="Gemela fuga",-Parametros!$B$2,IF($K17="Gemela tono",$E17-Parametros!$B$2,0)))))))/1000) | M17: =L17-O17/2000 | N17: =L17+O17/2000 | O17: 20 | P17: 1
A18: 17 | B18: A | C18: Replicas con correccion de imagen | D18: 400 | E18: 200 | F18: 2 | G18: Enc | H18: Enc | I18: Apag | J18: Apag | K18: Imagen | L18: =IF($K18="Vista ancha",$D18+0.1,$D18+IF($K18="Fuga",0,IF($K18="Tono",$E18,IF($K18="Imagen",-$E18,IF($K18="Replica fuga",Parametros!$B$2,IF($K18="Replica tono",$E18+Parametros!$B$2,IF($K18="Gemela fuga",-Parametros!$B$2,IF($K18="Gemela tono",$E18-Parametros!$B$2,0)))))))/1000) | M18: =L18-O18/2000 | N18: =L18+O18/2000 | O18: 20 | P18: 1 | V18: Control de que la correccion de imagen sigue funcionando: deberia dar alrededor de -93 dBm.
A19: 18 | B19: A | C19: 4 MSPS | D19: 400 | E19: 200 | F19: 4 | G19: Enc | H19: Enc | I19: Apag | J19: Apag | K19: Vista ancha | L19: =IF($K19="Vista ancha",$D19+0.1,$D19+IF($K19="Fuga",0,IF($K19="Tono",$E19,IF($K19="Imagen",-$E19,IF($K19="Replica fuga",Parametros!$B$2,IF($K19="Replica tono",$E19+Parametros!$B$2,IF($K19="Gemela fuga",-Parametros!$B$2,IF($K19="Gemela tono",$E19-Parametros!$B$2,0)))))))/1000) | M19: =L19-O19/2000 | N19: =L19+O19/2000 | O19: 2600 | P19: 3 | U19: SI | V19: Tasa de muestreo en 4 MSPS y esperar 1 minuto. Si la consola muestra errores, cerrar el flujo desde su ventana, cambiar la tasa y volver a ejecutar. Anotar en Notas si alguna linea cambio de lugar respecto de la vista ancha del orden 1.
A20: 19 | B20: A | C20: 4 MSPS | D20: 400 | E20: 200 | F20: 4 | G20: Enc | H20: Enc | I20: Apag | J20: Apag | K20: Fuga | L20: =IF($K20="Vista ancha",$D20+0.1,$D20+IF($K20="Fuga",0,IF($K20="Tono",$E20,IF($K20="Imagen",-$E20,IF($K20="Replica fuga",Parametros!$B$2,IF($K20="Replica tono",$E20+Parametros!$B$2,IF($K20="Gemela fuga",-Parametros!$B$2,IF($K20="Gemela tono",$E20-Parametros!$B$2,0)))))))/1000) | M20: =L20-O20/2000 | N20: =L20+O20/2000 | O20: 20 | P20: 1
A21: 20 | B21: A | C21: 4 MSPS | D21: 400 | E21: 200 | F21: 4 | G21: Enc | H21: Enc | I21: Apag | J21: Apag | K21: Tono | L21: =IF($K21="Vista ancha",$D21+0.1,$D21+IF($K21="Fuga",0,IF($K21="Tono",$E21,IF($K21="Imagen",-$E21,IF($K21="Replica fuga",Parametros!$B$2,IF($K21="Replica tono",$E21+Parametros!$B$2,IF($K21="Gemela fuga",-Parametros!$B$2,IF($K21="Gemela tono",$E21-Parametros!$B$2,0)))))))/1000) | M21: =L21-O21/2000 | N21: =L21+O21/2000 | O21: 20 | P21: 1
A22: 21 | B22: A | C22: 4 MSPS | D22: 400 | E22: 200 | F22: 4 | G22: Enc | H22: Enc | I22: Apag | J22: Apag | K22: Imagen | L22: =IF($K22="Vista ancha",$D22+0.1,$D22+IF($K22="Fuga",0,IF($K22="Tono",$E22,IF($K22="Imagen",-$E22,IF($K22="Replica fuga",Parametros!$B$2,IF($K22="Replica tono",$E22+Parametros!$B$2,IF($K22="Gemela fuga",-Parametros!$B$2,IF($K22="Gemela tono",$E22-Parametros!$B$2,0)))))))/1000) | M22: =L22-O22/2000 | N22: =L22+O22/2000 | O22: 20 | P22: 1 | V22: Si la imagen quedo por encima de -88 dBm, el filtro nuevo cambio el desbalance: recalcular c con el bloque Imagen de la hoja Busqueda antes de seguir, y anotar el c nuevo en Notas.
A23: 22 | B23: A | C23: 4 MSPS | D23: 400 | E23: 200 | F23: 4 | G23: Enc | H23: Enc | I23: Apag | J23: Apag | K23: Replica fuga | L23: =IF($K23="Vista ancha",$D23+0.1,$D23+IF($K23="Fuga",0,IF($K23="Tono",$E23,IF($K23="Imagen",-$E23,IF($K23="Replica fuga",Parametros!$B$2,IF($K23="Replica tono",$E23+Parametros!$B$2,IF($K23="Gemela fuga",-Parametros!$B$2,IF($K23="Gemela tono",$E23-Parametros!$B$2,0)))))))/1000) | M23: =L23-O23/2000 | N23: =L23+O23/2000 | O23: 20 | P23: 1 | V23: Si no aparece en la frecuencia esperada, buscarla en la vista ancha y anotar donde esta.
A24: 23 | B24: A | C24: 4 MSPS | D24: 400 | E24: 200 | F24: 4 | G24: Enc | H24: Enc | I24: Apag | J24: Apag | K24: Replica tono | L24: =IF($K24="Vista ancha",$D24+0.1,$D24+IF($K24="Fuga",0,IF($K24="Tono",$E24,IF($K24="Imagen",-$E24,IF($K24="Replica fuga",Parametros!$B$2,IF($K24="Replica tono",$E24+Parametros!$B$2,IF($K24="Gemela fuga",-Parametros!$B$2,IF($K24="Gemela tono",$E24-Parametros!$B$2,0)))))))/1000) | M24: =L24-O24/2000 | N24: =L24+O24/2000 | O24: 20 | P24: 1
A25: 24 | B25: A | C25: 4 MSPS | D25: 400 | E25: 200 | F25: 4 | G25: Enc | H25: Enc | I25: Apag | J25: Apag | K25: Gemela fuga | L25: =IF($K25="Vista ancha",$D25+0.1,$D25+IF($K25="Fuga",0,IF($K25="Tono",$E25,IF($K25="Imagen",-$E25,IF($K25="Replica fuga",Parametros!$B$2,IF($K25="Replica tono",$E25+Parametros!$B$2,IF($K25="Gemela fuga",-Parametros!$B$2,IF($K25="Gemela tono",$E25-Parametros!$B$2,0)))))))/1000) | M25: =L25-O25/2000 | N25: =L25+O25/2000 | O25: 20 | P25: 1 | V25: Estas dos gemelas son la referencia para ver si la cancelacion crea algo del otro lado.
A26: 25 | B26: A | C26: 4 MSPS | D26: 400 | E26: 200 | F26: 4 | G26: Enc | H26: Enc | I26: Apag | J26: Apag | K26: Gemela tono | L26: =IF($K26="Vista ancha",$D26+0.1,$D26+IF($K26="Fuga",0,IF($K26="Tono",$E26,IF($K26="Imagen",-$E26,IF($K26="Replica fuga",Parametros!$B$2,IF($K26="Replica tono",$E26+Parametros!$B$2,IF($K26="Gemela fuga",-Parametros!$B$2,IF($K26="Gemela tono",$E26-Parametros!$B$2,0)))))))/1000) | M26: =L26-O26/2000 | N26: =L26+O26/2000 | O26: 20 | P26: 1
A27: 26 | B27: A | C27: 4 MSPS, frecuencia exacta | D27: 400 | E27: 200 | F27: 4 | G27: Enc | H27: Enc | I27: Apag | J27: Apag | K27: Fuga | L27: =IF($K27="Vista ancha",$D27+0.1,$D27+IF($K27="Fuga",0,IF($K27="Tono",$E27,IF($K27="Imagen",-$E27,IF($K27="Replica fuga",Parametros!$B$2,IF($K27="Replica tono",$E27+Parametros!$B$2,IF($K27="Gemela fuga",-Parametros!$B$2,IF($K27="Gemela tono",$E27-Parametros!$B$2,0)))))))/1000) | M27: =L27-O27/2000 | N27: =L27+O27/2000 | O27: 2 | P27: 0.2
A28: 27 | B28: A | C28: 4 MSPS, frecuencia exacta | D28: 400 | E28: 200 | F28: 4 | G28: Enc | H28: Enc | I28: Apag | J28: Apag | K28: Replica fuga | L28: =IF($K28="Vista ancha",$D28+0.1,$D28+IF($K28="Fuga",0,IF($K28="Tono",$E28,IF($K28="Imagen",-$E28,IF($K28="Replica fuga",Parametros!$B$2,IF($K28="Replica tono",$E28+Parametros!$B$2,IF($K28="Gemela fuga",-Parametros!$B$2,IF($K28="Gemela tono",$E28-Parametros!$B$2,0)))))))/1000) | M28: =L28-O28/2000 | N28: =L28+O28/2000 | O28: 2 | P28: 0.2 | V28: Si la hoja Parametros muestra una diferencia de mas de 50 Hz entre 2 y 4 MSPS, la espuria sale del reloj de muestras. Anotarlo y seguir igual, con el corrimiento de 4 MSPS.
A29: 28 | B29: B | C29: Cancelacion de la replica de la fuga | D29: 400 | E29: 200 | F29: 4 | G29: Enc | H29: Enc | I29: Apag | J29: Apag | K29: Replica fuga | L29: =IF($K29="Vista ancha",$D29+0.1,$D29+IF($K29="Fuga",0,IF($K29="Tono",$E29,IF($K29="Imagen",-$E29,IF($K29="Replica fuga",Parametros!$B$2,IF($K29="Replica tono",$E29+Parametros!$B$2,IF($K29="Gemela fuga",-Parametros!$B$2,IF($K29="Gemela tono",$E29-Parametros!$B$2,0)))))))/1000) | M29: =L29-O29/2000 | N29: =L29+O29/2000 | O29: 20 | P29: 1 | U29: SI | V29: Referencia antes de cancelar. Poner el corrimiento grueso del flujo en el valor de Parametros B2, redondeado a 0,01 kHz (con 4 MSPS usar Parametros B4 si es distinto), y el ajuste fino en 0.
A30: 29 | B30: B | C30: Cancelacion de la replica de la fuga | D30: 400 | E30: 200 | F30: 4 | G30: Enc | H30: Enc | I30: Enc | J30: Apag | K30: Replica fuga | L30: =IF($K30="Vista ancha",$D30+0.1,$D30+IF($K30="Fuga",0,IF($K30="Tono",$E30,IF($K30="Imagen",-$E30,IF($K30="Replica fuga",Parametros!$B$2,IF($K30="Replica tono",$E30+Parametros!$B$2,IF($K30="Gemela fuga",-Parametros!$B$2,IF($K30="Gemela tono",$E30-Parametros!$B$2,0)))))))/1000) | M30: =L30-O30/2000 | N30: =L30+O30/2000 | O30: 20 | P30: 1 | Q30: -59 | R30: 0 | V30: Encender e. Promediado APAGADO. Si el marcador sube y baja en forma periodica, es el batido: mover el ajuste fino hasta que el periodo supere los 10 segundos. Si apenas se mueve, subir el nivel de e 10 dB. Anotar en Notas el valor final del fino y si el batido se pudo frenar. SI EL BATIDO ES ERRATICO O NO SE PUEDE FRENAR, la espuria no esta amarrada al reloj: saltar al orden 33, verificacion.
A31: 30 | B31: B | C31: Cancelacion de la replica de la fuga | D31: 400 | E31: 200 | F31: 4 | G31: Enc | H31: Enc | I31: Enc | J31: Apag | K31: Replica fuga | L31: =IF($K31="Vista ancha",$D31+0.1,$D31+IF($K31="Fuga",0,IF($K31="Tono",$E31,IF($K31="Imagen",-$E31,IF($K31="Replica fuga",Parametros!$B$2,IF($K31="Replica tono",$E31+Parametros!$B$2,IF($K31="Gemela fuga",-Parametros!$B$2,IF($K31="Gemela tono",$E31-Parametros!$B$2,0)))))))/1000) | M31: =L31-O31/2000 | N31: =L31+O31/2000 | O31: 20 | P31: 1 | Q31: =Busqueda!$B$26 | R31: =Busqueda!$B$25 | U31: SI | V31: Antes de esta fila, completar el bloque e de la hoja Busqueda: tres lecturas con promediado 16. Despues poner e en el nivel y la fase calculados (columnas de nivel y fase de esta fila) y medir. Si queres, retocar fase +/-2 grados y nivel +/-0,5 dB y anotar el mejor en Notas.
A32: 31 | B32: B | C32: Cancelacion de la replica del tono | D32: 400 | E32: 200 | F32: 4 | G32: Enc | H32: Enc | I32: Enc | J32: Apag | K32: Replica tono | L32: =IF($K32="Vista ancha",$D32+0.1,$D32+IF($K32="Fuga",0,IF($K32="Tono",$E32,IF($K32="Imagen",-$E32,IF($K32="Replica fuga",Parametros!$B$2,IF($K32="Replica tono",$E32+Parametros!$B$2,IF($K32="Gemela fuga",-Parametros!$B$2,IF($K32="Gemela tono",$E32-Parametros!$B$2,0)))))))/1000) | M32: =L32-O32/2000 | N32: =L32+O32/2000 | O32: 20 | P32: 1 | U32: SI | V32: Referencia antes de cancelar, con e ya aplicado.
A33: 32 | B33: B | C33: Cancelacion de la replica del tono | D33: 400 | E33: 200 | F33: 4 | G33: Enc | H33: Enc | I33: Enc | J33: Enc | K33: Replica tono | L33: =IF($K33="Vista ancha",$D33+0.1,$D33+IF($K33="Fuga",0,IF($K33="Tono",$E33,IF($K33="Imagen",-$E33,IF($K33="Replica fuga",Parametros!$B$2,IF($K33="Replica tono",$E33+Parametros!$B$2,IF($K33="Gemela fuga",-Parametros!$B$2,IF($K33="Gemela tono",$E33-Parametros!$B$2,0)))))))/1000) | M33: =L33-O33/2000 | N33: =L33+O33/2000 | O33: 20 | P33: 1 | Q33: =Busqueda!$B$41 | R33: =Busqueda!$B$40 | U33: SI | V33: Completar el bloque d de la hoja Busqueda con d en -52 dB (tres lecturas). Despues poner d en el nivel y la fase calculados y medir.
A34: 33 | B34: B | C34: Verificacion | D34: 400 | E34: 200 | F34: 4 | G34: Enc | H34: Enc | I34: Enc | J34: Enc | K34: Gemela fuga | L34: =IF($K34="Vista ancha",$D34+0.1,$D34+IF($K34="Fuga",0,IF($K34="Tono",$E34,IF($K34="Imagen",-$E34,IF($K34="Replica fuga",Parametros!$B$2,IF($K34="Replica tono",$E34+Parametros!$B$2,IF($K34="Gemela fuga",-Parametros!$B$2,IF($K34="Gemela tono",$E34-Parametros!$B$2,0)))))))/1000) | M34: =L34-O34/2000 | N34: =L34+O34/2000 | O34: 20 | P34: 1 | U34: SI | V34: Todo encendido. Comparar con las gemelas medidas a 4 MSPS antes de cancelar.
A35: 34 | B35: B | C35: Verificacion | D35: 400 | E35: 200 | F35: 4 | G35: Enc | H35: Enc | I35: Enc | J35: Enc | K35: Gemela tono | L35: =IF($K35="Vista ancha",$D35+0.1,$D35+IF($K35="Fuga",0,IF($K35="Tono",$E35,IF($K35="Imagen",-$E35,IF($K35="Replica fuga",Parametros!$B$2,IF($K35="Replica tono",$E35+Parametros!$B$2,IF($K35="Gemela fuga",-Parametros!$B$2,IF($K35="Gemela tono",$E35-Parametros!$B$2,0)))))))/1000) | M35: =L35-O35/2000 | N35: =L35+O35/2000 | O35: 20 | P35: 1 | U35: SI
A36: 35 | B36: B | C36: Verificacion | D36: 400 | E36: 200 | F36: 4 | G36: Enc | H36: Enc | I36: Enc | J36: Enc | K36: Tono | L36: =IF($K36="Vista ancha",$D36+0.1,$D36+IF($K36="Fuga",0,IF($K36="Tono",$E36,IF($K36="Imagen",-$E36,IF($K36="Replica fuga",Parametros!$B$2,IF($K36="Replica tono",$E36+Parametros!$B$2,IF($K36="Gemela fuga",-Parametros!$B$2,IF($K36="Gemela tono",$E36-Parametros!$B$2,0)))))))/1000) | M36: =L36-O36/2000 | N36: =L36+O36/2000 | O36: 20 | P36: 1
A37: 36 | B37: B | C37: Verificacion | D37: 400 | E37: 200 | F37: 4 | G37: Enc | H37: Enc | I37: Enc | J37: Enc | K37: Fuga | L37: =IF($K37="Vista ancha",$D37+0.1,$D37+IF($K37="Fuga",0,IF($K37="Tono",$E37,IF($K37="Imagen",-$E37,IF($K37="Replica fuga",Parametros!$B$2,IF($K37="Replica tono",$E37+Parametros!$B$2,IF($K37="Gemela fuga",-Parametros!$B$2,IF($K37="Gemela tono",$E37-Parametros!$B$2,0)))))))/1000) | M37: =L37-O37/2000 | N37: =L37+O37/2000 | O37: 20 | P37: 1
A38: 37 | B38: B | C38: Verificacion | D38: 400 | E38: 200 | F38: 4 | G38: Enc | H38: Enc | I38: Enc | J38: Enc | K38: Imagen | L38: =IF($K38="Vista ancha",$D38+0.1,$D38+IF($K38="Fuga",0,IF($K38="Tono",$E38,IF($K38="Imagen",-$E38,IF($K38="Replica fuga",Parametros!$B$2,IF($K38="Replica tono",$E38+Parametros!$B$2,IF($K38="Gemela fuga",-Parametros!$B$2,IF($K38="Gemela tono",$E38-Parametros!$B$2,0)))))))/1000) | M38: =L38-O38/2000 | N38: =L38+O38/2000 | O38: 20 | P38: 1
A39: 38 | B39: B | C39: Verificacion | D39: 400 | E39: 200 | F39: 4 | G39: Enc | H39: Enc | I39: Enc | J39: Enc | K39: Vista ancha | L39: =IF($K39="Vista ancha",$D39+0.1,$D39+IF($K39="Fuga",0,IF($K39="Tono",$E39,IF($K39="Imagen",-$E39,IF($K39="Replica fuga",Parametros!$B$2,IF($K39="Replica tono",$E39+Parametros!$B$2,IF($K39="Gemela fuga",-Parametros!$B$2,IF($K39="Gemela tono",$E39-Parametros!$B$2,0)))))))/1000) | M39: =L39-O39/2000 | N39: =L39+O39/2000 | O39: 2600 | P39: 3 | U39: SI | V39: Comparar con la vista ancha de 4 MSPS: no deberia aparecer ninguna linea nueva.
A40: 39 | B40: B | C40: Control de que el nulo se mantiene | D40: 400 | E40: 200 | F40: 4 | G40: Enc | H40: Enc | I40: Enc | J40: Enc | K40: Replica fuga | L40: =IF($K40="Vista ancha",$D40+0.1,$D40+IF($K40="Fuga",0,IF($K40="Tono",$E40,IF($K40="Imagen",-$E40,IF($K40="Replica fuga",Parametros!$B$2,IF($K40="Replica tono",$E40+Parametros!$B$2,IF($K40="Gemela fuga",-Parametros!$B$2,IF($K40="Gemela tono",$E40-Parametros!$B$2,0)))))))/1000) | M40: =L40-O40/2000 | N40: =L40+O40/2000 | O40: 20 | P40: 1 | V40: Sin tocar nada desde la cancelacion. Si subio mas de 6 dB, el nulo deriva: anotarlo.
...

Sheet Parametros
A1: Parametro | B1: Valor | C1: De donde sale
A2: Corrimiento de la espuria usado en las formulas (kHz) | B2: =IF(B3="",-937.2,B3) | C2: Si todavia no se midio con precision, usa -937,2 kHz (EXP-08)
A3: Corrimiento medido con precision, 2 MSPS (kHz) | B3: =IF(OR(Datos!$S$9="",Datos!$S$10=""),"",(Datos!$S$10-Datos!$S$9)*1000) | C3: Ordenes 8 y 9 de Datos
A4: Corrimiento medido con precision, 4 MSPS (kHz) | B4: =IF(OR(Datos!$S$27="",Datos!$S$28=""),"",(Datos!$S$28-Datos!$S$27)*1000) | C4: Ordenes 26 y 27 de Datos
A5: Diferencia 4 MSPS menos 2 MSPS (Hz) | B5: =IF(OR(B3="",B4=""),"",(B4-B3)*1000) | C5: Mas de 50 Hz: la espuria sale del reloj de muestras

Sheet Busqueda
A1: Ejemplo: imagen del EXP-09 (lecturas tomadas del ajuste de las 13 fases, no medidas asi)
A2: Nivel de la linea con la correccion apagada (dBm) | B2: -75.8 | C2: Imagen sin correccion medida en el EXP-09
A3: Nivel de correccion usado en las tres lecturas (dB) | B3: -34 | C3: El que queda puesto en el flujo durante las tres lecturas
A4: Fase de arranque (grados) | B4: 0 | C4: Si alguna lectura queda cerca del piso, arrancar en 60 y repetir
A5: Lectura 1, fase = arranque (dBm) | B5: -86.8 | C5: Con promediado 16
A6: Fase de la lectura 2 (grados) | B6: =MOD(B4+120+180,360)-180
A7: Lectura 2 (dBm) | B7: -70.8
A8: Fase de la lectura 3 (grados) | B8: =MOD(B4+240+180,360)-180
A9: Lectura 3 (dBm) | B9: -69.7
A10: Fase optima (grados) | B10: =IF(AND(B2<>"",B5<>"",B7<>"",B9<>""),MOD(DEGREES(ATAN2((2/3)*(10^(B5/10)-0.5*10^(B7/10)-0.5*10^(B9/10)),((10^(B7/10))-(10^(B9/10)))/SQRT(3)))+B4+360,360)-180,"") | C10: Punto opuesto al maximo de la suma
A11: Nivel optimo (dB) | B11: =IF(AND(B2<>"",B5<>"",B7<>"",B9<>""),IF((((10^(B5/10))+(10^(B7/10))+(10^(B9/10)))/3-10^(B2/10))<=0,"",B3+10*LOG10(10^(B2/10)/(((10^(B5/10))+(10^(B7/10))+(10^(B9/10)))/3-10^(B2/10)))),"") | C11: Nivel usado mas lo que falta para igualar a la linea
A12: Control de calidad (ideal 1) | B12: =IF(AND(B2<>"",B5<>"",B7<>"",B9<>""),IF((((10^(B5/10))+(10^(B7/10))+(10^(B9/10)))/3-10^(B2/10))<=0,"",SQRT(((2/3)*(10^(B5/10)-0.5*10^(B7/10)-0.5*10^(B9/10)))^2+(((10^(B7/10))-(10^(B9/10)))/SQRT(3))^2)/(2*SQRT(10^(B2/10)*(((10^(B5/10))+(10^(B7/10))+(10^(B9/10)))/3-10^(B2/10))))),"") | C12: Entre 0,8 y 1,2: lecturas coherentes. Fuera de eso, repetir con mas promediado
A13: Estado | B13: =IF(NOT(AND(B2<>"",B5<>"",B7<>"",B9<>"")),"Faltan lecturas",IF((((10^(B5/10))+(10^(B7/10))+(10^(B9/10)))/3-10^(B2/10))<=0,"Revisar: la correccion no suma nada, subir su nivel 10 dB",IF(ABS(B12-1)>0.2,"Lecturas poco coherentes: repetir","OK")))
A16: e: cancelacion de la replica de la fuga (4 MSPS)
A17: Nivel de la linea con la correccion apagada (dBm) | B17: =IF(Datos!$T$29="","",Datos!$T$29) | C17: Se toma sola del orden 28 de Datos
A18: Nivel de correccion usado en las tres lecturas (dB) | B18: -59 | C18: El que queda puesto en el flujo durante las tres lecturas
A19: Fase de arranque (grados) | B19: 0 | C19: Si alguna lectura queda cerca del piso, arrancar en 60 y repetir
A20: Lectura 1, fase = arranque (dBm) | C20: Con promediado 16
A21: Fase de la lectura 2 (grados) | B21: =MOD(B19+120+180,360)-180
A22: Lectura 2 (dBm)
A23: Fase de la lectura 3 (grados) | B23: =MOD(B19+240+180,360)-180
A24: Lectura 3 (dBm)
A25: Fase optima (grados) | B25: =IF(AND(B17<>"",B20<>"",B22<>"",B24<>""),MOD(DEGREES(ATAN2((2/3)*(10^(B20/10)-0.5*10^(B22/10)-0.5*10^(B24/10)),((10^(B22/10))-(10^(B24/10)))/SQRT(3)))+B19+360,360)-180,"") | C25: Punto opuesto al maximo de la suma
A26: Nivel optimo (dB) | B26: =IF(AND(B17<>"",B20<>"",B22<>"",B24<>""),IF((((10^(B20/10))+(10^(B22/10))+(10^(B24/10)))/3-10^(B17/10))<=0,"",B18+10*LOG10(10^(B17/10)/(((10^(B20/10))+(10^(B22/10))+(10^(B24/10)))/3-10^(B17/10)))),"") | C26: Nivel usado mas lo que falta para igualar a la linea
A27: Control de calidad (ideal 1) | B27: =IF(AND(B17<>"",B20<>"",B22<>"",B24<>""),IF((((10^(B20/10))+(10^(B22/10))+(10^(B24/10)))/3-10^(B17/10))<=0,"",SQRT(((2/3)*(10^(B20/10)-0.5*10^(B22/10)-0.5*10^(B24/10)))^2+(((10^(B22/10))-(10^(B24/10)))/SQRT(3))^2)/(2*SQRT(10^(B17/10)*(((10^(B20/10))+(10^(B22/10))+(10^(B24/10)))/3-10^(B17/10))))),"") | C27: Entre 0,8 y 1,2: lecturas coherentes. Fuera de eso, repetir con mas promediado
A28: Estado | B28: =IF(NOT(AND(B17<>"",B20<>"",B22<>"",B24<>"")),"Faltan lecturas",IF((((10^(B20/10))+(10^(B22/10))+(10^(B24/10)))/3-10^(B17/10))<=0,"Revisar: la correccion no suma nada, subir su nivel 10 dB",IF(ABS(B27-1)>0.2,"Lecturas poco coherentes: repetir","OK")))
A31: d: cancelacion de la replica del tono (4 MSPS, con e aplicado)
A32: Nivel de la linea con la correccion apagada (dBm) | B32: =IF(Datos!$T$32="","",Datos!$T$32) | C32: Se toma sola del orden 31 de Datos
A33: Nivel de correccion usado en las tres lecturas (dB) | B33: -52 | C33: El que queda puesto en el flujo durante las tres lecturas
A34: Fase de arranque (grados) | B34: 0 | C34: Si alguna lectura queda cerca del piso, arrancar en 60 y repetir
A35: Lectura 1, fase = arranque (dBm) | C35: Con promediado 16
A36: Fase de la lectura 2 (grados) | B36: =MOD(B34+120+180,360)-180
A37: Lectura 2 (dBm)
A38: Fase de la lectura 3 (grados) | B38: =MOD(B34+240+180,360)-180
A39: Lectura 3 (dBm)
A40: Fase optima (grados) | B40: =IF(AND(B32<>"",B35<>"",B37<>"",B39<>""),MOD(DEGREES(ATAN2((2/3)*(10^(B35/10)-0.5*10^(B37/10)-0.5*10^(B39/10)),((10^(B37/10))-(10^(B39/10)))/SQRT(3)))+B34+360,360)-180,"") | C40: Punto opuesto al maximo de la suma
A41: Nivel optimo (dB) | B41: =IF(AND(B32<>"",B35<>"",B37<>"",B39<>""),IF((((10^(B35/10))+(10^(B37/10))+(10^(B39/10)))/3-10^(B32/10))<=0,"",B33+10*LOG10(10^(B32/10)/(((10^(B35/10))+(10^(B37/10))+(10^(B39/10)))/3-10^(B32/10)))),"") | C41: Nivel usado mas lo que falta para igualar a la linea
A42: Control de calidad (ideal 1) | B42: =IF(AND(B32<>"",B35<>"",B37<>"",B39<>""),IF((((10^(B35/10))+(10^(B37/10))+(10^(B39/10)))/3-10^(B32/10))<=0,"",SQRT(((2/3)*(10^(B35/10)-0.5*10^(B37/10)-0.5*10^(B39/10)))^2+(((10^(B37/10))-(10^(B39/10)))/SQRT(3))^2)/(2*SQRT(10^(B32/10)*(((10^(B35/10))+(10^(B37/10))+(10^(B39/10)))/3-10^(B32/10))))),"") | C42: Entre 0,8 y 1,2: lecturas coherentes. Fuera de eso, repetir con mas promediado
A43: Estado | B43: =IF(NOT(AND(B32<>"",B35<>"",B37<>"",B39<>"")),"Faltan lecturas",IF((((10^(B35/10))+(10^(B37/10))+(10^(B39/10)))/3-10^(B32/10))<=0,"Revisar: la correccion no suma nada, subir su nivel 10 dB",IF(ABS(B42-1)>0.2,"Lecturas poco coherentes: repetir","OK")))
A46: Imagen: solo si hay que recalcular c con 4 MSPS
...

Sheet Resumen
A1: Resultado | B1: Valor | C1: Como leerlo
A2: DIAGNOSTICO, 2 MSPS
A3: Replica de la fuga respecto de la fuga (dBc) | B3: =IF(OR(Datos!$T$5="",Datos!$T$3=""),"",Datos!$T$5-Datos!$T$3) | C3: EXP-08: unos -52 dBc
A4: Replica del tono respecto del tono (dBc) | B4: =IF(OR(Datos!$T$6="",Datos!$T$4=""),"",Datos!$T$6-Datos!$T$4) | C4: Igual a la anterior: la espuria es una linea del oscilador local
A5: Gemela de la fuga respecto de la fuga (dBc) | B5: =IF(OR(Datos!$T$7="",Datos!$T$3=""),"",Datos!$T$7-Datos!$T$3) | C5: Si existe: modulacion simetrica, probable fuente conmutada
A6: Gemela del tono respecto del tono (dBc) | B6: =IF(OR(Datos!$T$8="",Datos!$T$4=""),"",Datos!$T$8-Datos!$T$4)
A7: Replica de la fuga: tono apagado menos encendido (dB) | B7: =IF(OR(Datos!$T$11="",Datos!$T$5=""),"",Datos!$T$11-Datos!$T$5) | C7: Cerca de 0: no depende del tono
A8: Replica del tono con el tono apagado (dBm) | B8: =IF(Datos!$T$12="","",Datos!$T$12) | C8: Deberia ser el piso
A9: Tono: correccion de imagen encendida menos apagada (dB) | B9: =IF(COUNT(Datos!$T$4,Datos!$T$14,Datos!$T$13,Datos!$T$15)<4,"",AVERAGE(Datos!$T$13,Datos!$T$15)-AVERAGE(Datos!$T$4,Datos!$T$14)) | C9: Prediccion: 0,00 dB. Menos de 0,1 dB confirma que la correccion no toca el tono
A10: Replica de la fuga: con correccion de imagen menos sin (dB) | B10: =IF(OR(Datos!$T$16="",Datos!$T$5=""),"",Datos!$T$16-Datos!$T$5) | C10: Prediccion: 0
A11: Replica del tono: con correccion de imagen menos sin (dB) | B11: =IF(OR(Datos!$T$17="",Datos!$T$6=""),"",Datos!$T$17-Datos!$T$6) | C11: Prediccion: 0
A12: Corrimiento exacto con 2 MSPS (kHz) | B12: =Parametros!B3
A13: DIAGNOSTICO, 4 MSPS
A14: Corrimiento exacto con 4 MSPS (kHz) | B14: =Parametros!B4
A15: Diferencia de corrimiento 4 menos 2 MSPS (Hz) | B15: =Parametros!B5 | C15: Mas de 50 Hz: sale del reloj de muestras
A16: Fuga: 4 MSPS menos 2 MSPS (dB) | B16: =IF(OR(Datos!$T$20="",Datos!$T$3=""),"",Datos!$T$20-Datos!$T$3)
A17: Rechazo de imagen corregido con 4 MSPS (dB) | B17: =IF(OR(Datos!$T$21="",Datos!$T$22=""),"",Datos!$T$21-Datos!$T$22) | C17: EXP-09 con 2 MSPS: unos 52 dB
A18: Replica de la fuga con 4 MSPS (dBc) | B18: =IF(OR(Datos!$T$23="",Datos!$T$20=""),"",Datos!$T$23-Datos!$T$20)
A19: Replica del tono con 4 MSPS (dBc) | B19: =IF(OR(Datos!$T$24="",Datos!$T$21=""),"",Datos!$T$24-Datos!$T$21)
A20: CANCELACION, 4 MSPS
A21: Mejora en la replica de la fuga (dB) | B21: =IF(OR(Datos!$T$29="",Datos!$T$31=""),"",Datos!$T$29-Datos!$T$31) | C21: 15 dB o mas: eliminada en forma eficaz
A22: Mejora en la replica del tono (dB) | B22: =IF(OR(Datos!$T$32="",Datos!$T$33=""),"",Datos!$T$32-Datos!$T$33) | C22: 15 dB o mas: eliminada en forma eficaz
A23: Gemela de la fuga: despues menos antes (dB) | B23: =IF(OR(Datos!$T$34="",Datos!$T$25=""),"",Datos!$T$34-Datos!$T$25) | C23: Cerca de 0: la cancelacion no crea nada del otro lado
A24: Gemela del tono: despues menos antes (dB) | B24: =IF(OR(Datos!$T$35="",Datos!$T$26=""),"",Datos!$T$35-Datos!$T$26) | C24: Cerca de 0: idem
A25: Tono: todo encendido menos solo imagen (dB) | B25: =IF(OR(Datos!$T$36="",Datos!$T$21=""),"",Datos!$T$36-Datos!$T$21) | C25: Deberia quedar dentro de 0,1 dB
A26: Fuga: todo encendido menos solo imagen (dB) | B26: =IF(OR(Datos!$T$37="",Datos!$T$20=""),"",Datos!$T$37-Datos!$T$20) | C26: Deberia quedar dentro de 0,1 dB
A27: Deriva del nulo de la replica de la fuga (dB) | B27: =IF(OR(Datos!$T$40="",Datos!$T$31=""),"",Datos!$T$40-Datos!$T$31) | C27: Mas de 6 dB: el nulo no es estable
A28: Deriva del nulo de la replica del tono (dB) | B28: =IF(OR(Datos!$T$41="",Datos!$T$33=""),"",Datos!$T$41-Datos!$T$33)
A29: OPCIONAL, 600 MHz CON LOS MISMOS e Y d
A30: Mejora en la replica de la fuga (dB) | B30: =IF(OR(Datos!$T$42="",Datos!$T$43=""),"",Datos!$T$42-Datos!$T$43) | C30: Si es mucho menor que en 400 MHz, hace falta un e por portadora
A31: Mejora en la replica del tono (dB) | B31: =IF(OR(Datos!$T$44="",Datos!$T$45=""),"",Datos!$T$44-Datos!$T$45)
